Workbook

Sheet 摸底成績
A1: 2024 | C1: 學年 | D1: 第一段 | G1: 英讀 | H1: 科摸底成績
A2: 本校 學籍號 | B2: 學號 | C2: 高三1 | D2: 摸底 | E2: 本校 學籍號 | F2: 學號 | G2: 高三2 | H2: 摸底 | I2: 本校 學籍號 | J2: 學號 | K2: 高三3 | L2: 摸底 | M2: 本校 學籍號 | N2: 學號 | O2: 高三4 | P2: 摸底 | Q2: 本校 學籍號 | R2: 學號 | S2: 高三5 | T2: 摸底 | U2: 本校 學籍號 | V2: 學號 | W2: 高三6 | X2: 摸底 | Y2: 本校 學籍號 | Z2: 學號 | AA2: 高三7 | AB2: 摸底 | AC2: 本校 學籍號 | AD2: 學號 | AE2: 高三8 | AF2: 摸底 | AG2: 本校 學籍號 | AH2: 學號 | AI2: 高三9 | AJ2: 摸底
A4: 20210198 | B4: 1 | C4: 卜啟韜 | D4: 41.5 | E4: 20190194 | F4: 1 | G4: 何亦琳 | H4: 91 | I4: 20230213 | J4: 1 | K4: 尤嘉杰 | L4: 74.5 | M4: 20190043 | N4: 1 | O4: 王家銘 | P4: 34 | Q4: 20190080 | R4: 1 | S4: 吳翠瑩 | T4: 83.5 | U4: 20190231 | V4: 1 | W4: 尤欣鈮 | X4: 75.5 | Y4: 20190028 | Z4: 1 | AA4: 王楚怡 | AB4: 28.5 | AC4: 20220088 | AD4: 1 | AE4: 王語 | AF4: 57 | AG4: 20190164 | AH4: 1 | AI4: 王思琦 | AJ4: 32.5
A5: 20230214 | B5: 2 | C5: 尤鉑霖 | D5: 51 | E5: 20200072 | F5: 2 | G5: 李鑫 | H5: 64 | I5: 20190061 | J5: 2 | K5: 尹霖 | L5: 74.5 | M5: 20220053 | N5: 2 | O5: 伍智恒 | P5: 58 | Q5: 20230348 | R5: 2 | S5: 宋興喆 | T5: 94 | U5: 20190004 | V5: 2 | W5: 王馨如 | X5: 56.5 | Y5: 20122143 | Z5: 2 | AA5: 叶浩釗 | AB5: 76.5 | AC5: 20190046 | AD5: 2 | AE5: 吳詠欣 | AF5: 33 | AG5: 20230302 | AH5: 2 | AI5: 甘永康 | AJ5: 74
A6: 20190086 | B6: 3 | C6: 尹智成 | D6: 63 | E6: 20102031 | F6: 3 | G6: 杜家駿 | H6: 35 | I6: 20097078 | J6: 3 | K6: 王子璇 | L6: 59 | M6: 20220090 | N6: 3 | O6: 何盛林 | P6: 75 | Q6: 20190190 | R6: 3 | S6: 李嘉杰 | T6: 68 | U6: 20210122 | V6: 3 | W6: 石子伊 | X6: 66 | Y6: 20133052 | Z6: 3 | AA6: 伍錦稀 | AB6: 42 | AC6: 20220164 | AD6: 3 | AE6: 吳曉寧 | AF6: 87.5 | AG6: 20143114 | AH6: 3 | AI6: 何海樂 | AJ6: 87
A7: 20230295 | B7: 4 | C7: 王清晨 | D7: 88.5 | E7: 20180007 | F7: 4 | G7: 林佩怡 | H7: 40 | I7: 20200074 | J7: 4 | K7: 古凌嫣 | L7: 88 | M7: 20190011 | N7: 4 | O7: 吳俊賢 | P7: 29.5 | Q7: 20122139 | R7: 4 | S7: 林子俊 | T7: 83.5 | U7: 20220101 | V7: 4 | W7: 余珊姍 | X7: 35 | Y7: 20102002 | Z7: 4 | AA7: 朱詠錡 | AB7: 82.5 | AC7: 20180063 | AD7: 4 | AE7: 呂善怡 | AF7: 35.5 | AG7: 20190089 | AH7: 4 | AI7: 何潔欣 | AJ7: 63.5
A8: 20220187 | B8: 5 | C8: 何彥林 | D8: 72 | E8: 20102034 | F8: 5 | G8: 林俊業 | H8: 64 | I8: 20200175 | J8: 5 | K8: 伍蕙君 | L8: 64 | M8: 20230298 | N8: 5 | O8: 李凱璇 | P8: 74.5 | Q8: 20220175 | R8: 5 | S8: 林靖瑜 | T8: 39 | U8: 20190012 | V8: 5 | W8: 吳詩婷 | X8: 49 | Y8: 20190236 | Z8: 5 | AA8: 江庭瀚 | AB8: 33.5 | AC8: 20220225 | AD8: 5 | AE8: 李方萌 | AF8: 74 | AG8: 20190042 | AH8: 5 | AI8: 吳海儀 | AJ8: 76.5
A9: 20133010 | B9: 6 | C9: 何詠宜 | D9: 56.5 | E9: 20153065 | F9: 6 | G9: 姚宏銘 | H9: 87.5 | I9: 20220220 | J9: 6 | K9: 何宇揚 | L9: 70 | M9: 20153078 | N9: 6 | O9: 林家逸 | P9: 37 | Q9: 20102035 | R9: 6 | S9: 唐海敏 | T9: 39 | U9: 20190063 | V9: 6 | W9: 吳艷銘 | X9: 82 | Y9: 20163044 | Z9: 6 | AA9: 何鎔熙 | AB9: 31.5 | AC9: 20220059 | AD9: 6 | AE9: 李宛霖 | AF9: 56 | AG9: 20220083 | AH9: 6 | AI9: 吳靜希 | AJ9: 68.5
A10: 20220081 | B10: 7 | C10: 吳宇施 | D10: 72 | E10: 20220084 | F10: 7 | G10: 唐詩堯 | H10: 65.5 | I10: 20210196 | J10: 7 | K10: 李蓬承 | L10: 43.5 | M10: 20190082 | N10: 7 | O10: 林靜瑜 | P10: 58.5 | Q10: 20220082 | R10: 7 | S10: 徐朗庭 | T10: 72.5 | U10: 20230310 | V10: 7 | W10: 呂靖雯 | X10: 66.5 | Y10: 20190213 | Z10: 7 | AA10: 吳思婷 | AB10: 37 | AC10: 20143015 | AD10: 7 | AE10: 李楚潼 | AF10: 82.5 | AG10: 20072002 | AH10: 7 | AI10: 岑佩穎 | AJ10: 35.5
A11: 20190179 | B11: 8 | C11: 吳東濠 | D11: 81.5 | E11: 20210163 | F11: 8 | G11: 崔仕宇 | H11: 67.5 | I11: 20102007 | J11: 8 | K11: 林汶暉 | L11: 48 | M11: 20220097 | N11: 8 | O11: 康昊明 | P11: 77.5 | Q11: 20220091 | R11: 8 | S11: 曹越 | T11: 71 | U11: 20210184 | V11: 8 | W11: 阮正坤 | X11: 67.5 | Y11: 20220228 | Z11: 8 | AA11: 吳騏彤 | AB11: 66 | AC11: 20220166 | AD11: 8 | AE11: 林心悅 | AF11: 58 | AG11: 20190070 | AH11: 8 | AI11: 李浚軒 | AJ11: 47
A12: 20190009 | B12: 9 | C12: 吳俊君 | D12: 63 | E12: 20190244 | F12: 9 | G12: 梁嘉軒 | H12: 66 | I12: 20220060 | J12: 9 | K12: 林翰儒 | L12: 84.5 | M12: 20220142 | N12: 9 | O12: 梁咏詩 | P12: 66.5 | Q12: 20122133 | R12: 9 | S12: 梁啓邦 | T12: 64 | U12: 20190163 | V12: 9 | W12: 施嘉鑫 | X12: 41 | Y12: 20173024 | Z12: 9 | AA12: 李伊聖 | AB12: 42 | AC12: 20210160 | AD12: 9 | AE12: 林志洵 | AF12: 88 | AG12: 20190022 | AH12: 9 | AI12: 林心瑜 | AJ12: 63
A13: 20153119 | B13: 10 | C13: 李杰成 | D13: 41 | E13: 20220085 | F13: 10 | G13: 梅俊銳 | H13: 60.5 | I13: 20163070 | J13: 10 | K13: 胡善杰 | L13: 93 | M13: 20220086 | N13: 10 | O13: 梁語倩 | P13: 82 | Q13: 20230301 | R13: 10 | S13: 莊欣怡 | T13: 55 | U13: 20190159 | V13: 10 | W13: 范永淇 | X13: 72.5 | Y13: 20102063 | Z13: 10 | AA13: 施美言 | AB13: 51 | AC13: 20163052 | AD13: 10 | AE13: 高柏研 | AF13: 77.5 | AG13: 20190192 | AH13: 10 | AI13: 林延聰 | AJ13: 46.5
A14: 20220219 | B14: 11 | C14: 李遠航 | D14: 74.5 | E14: 20173030 | F14: 11 | G14: 陳泓睿 | H14: 62.5 | I14: 20153045 | J14: 11 | K14: 梁家誠 | L14: 88.5 | M14: 20200095 | N14: 11 | O14: 陳子晴 | P14: 62 | Q14: 20220223 | R14: 11 | S14: 莊梓程 | T14: 71.5 | U14: 20153106 | V14: 11 | W14: 韋綺婷 | X14: 66.5 | Y14: 20102009 | Z14: 11 | AA14: 韋采倩 | AB14: 60.5 | AC14: 20210119 | AD14: 11 | AE14: 區愷迎 | AF14: 72.5 | AG14: 20190225 | AH14: 11 | AI14: 林彥霖 | AJ14: 67
A15: 20190044 | B15: 12 | C15: 杜珮瑩 | D15: 38 | E15: 20220066 | F15: 12 | G15: 陳智騫 | H15: 60 | I15: 20190111 | J15: 12 | K15: 許啓晟 | L15: 83.5 | M15: 20133015 | N15: 12 | O15: 陳俊良 | P15: 78.5 | Q15: 20163053 | R15: 12 | S15: 陳宏杰 | T15: 63 | U15: 20220069 | V15: 12 | W15: 孫芷軒 | X15: 54.5 | Y15: 20230315 | Z15: 12 | AA15: 夏清逸 | AB15: 22.5 | AC15: 20180080 | AD15: 12 | AE15: 崔婉瑩 | AF15: 41 | AG15: 20230294 | AH15: 12 | AI15: 洪凱鋒 | AJ15: 26
... A29: 20173023 | B29: 26 | C29: 盧銳軒 | D29: 82.5 | E29: 20133024 | F29: 26 | G29: 譚芷琦 | H29: 74 | I29: 20163081 | J29: 26 | K29: 鄭嘉怡 | L29: 52 | M29: 20240363 | N29: 26 | O29: 黃思棋 | P29: 53 | Q29: 20210222 | R29: 26 | S29: 謝瑞欽 | T29: 40.5 | U29: 20122136 | V29: 26 | W29: 趙浚鎬 | X29: 31.5 | Y29: 20180027 | Z29: 26 | AA29: 鄭佳鴻 | AB29: 32.5 | AC29: 20190027 | AD29: 26 | AE29: 黃曼茜 | AF29: 43 | AG29: 20190001 | AH29: 26 | AI29: 黃馨瑩 | AJ29: 68
A30: 20190041 | B30: 27 | C30: 蕭嘉濤 | D30: 60.5 | E30: 20220120 | F30: 27 | G30: 蘇聖鈞 | H30: 69 | I30: 20220095 | J30: 27 | K30: 黎晉彬 | L30: 94.5 | Q30: 20220089 | R30: 27 | S30: 羅毅泓 | T30: 62.5 | U30: 20190093 | V30: 27 | W30: 蔡嘉琪 | X30: 71 | Y30: 20190215 | Z30: 27 | AA30: 黎可盈 | AB30: 45.5 | AC30: 20133019 | AD30: 27 | AE30: 黃淑茵 | AF30: 48.5 | AG30: 20210259 | AH30: 27 | AI30: 楊子誼 | AJ30: 60.5
A31: 20220054 | B31: 28 | C31: 龐宏俊 | D31: 80.5 | U31: 20220098 | V31: 28 | W31: 鄧芷喬 | X31: 20.5 | Y31: 20220151 | Z31: 28 | AA31: 羅政軒 | AB31: 23 | AC31: 20190039 | AD31: 28 | AE31: 黃清森 | AF31: 28.5 | AG31: 20102021 | AH31: 28 | AI31: 葉凱瑩 | AJ31: 61
U32: 20190077 | V32: 29 | W32: 鄭家雯 | X32: 51.5 | Y32: 20190002 | Z32: 29 | AA32: 譚幸瑜 | AB32: 40.5 | AC32: 20210268 | AD32: 29 | AE32: 黃嘉銘 | AF32: 32 | AG32: 20190223 | AH32: 29 | AI32: 鄒子熙 | AJ32: 62
U33: 20190031 | V33: 30 | W33: 謝怡晴 | X33: 34 | Y33: 20102079 | Z33: 30 | AA33: 譚俊杰 | AB33: 72 | AC33: 20133025 | AD33: 30 | AE33: 黃曉晴 | AF33: 84 | AG33: 20190023 | AH33: 30 | AI33: 廖一鳴 | AJ33: 43.5
U34: 20102054 | V34: 31 | W34: 譚靖曦 | X34: 79.5 | Y34: 20143082 | Z34: 31 | AA34: 譚靖筠 | AB34: 82.5 | AC34: 20210183 | AD34: 31 | AE34: 潘偉汶 | AF34: 27 | AG34: 20102023 | AH34: 31 | AI34: 趙必麗 | AJ34: 79.5
U35: 20190202 | V35: 32 | W35: 關焯盈 | X35: 37 | Y35: 20102055 | Z35: 32 | AA35: 關智軒 | AB35: 64 | AC35: 20153057 | AD35: 32 | AE35: 黎毅莎 | AF35: 51.5 | AG35: 20210220 | AH35: 32 | AI35: 劉柯泓 | AJ35: 79
U36: 20220067 | V36: 33 | W36: 蘇梓謙 | X36: 56.5 | Y36: 20200213 | Z36: 33 | AA36: 龐軼文 | AB36: 71.5 | AC36: 20190045 | AD36: 33 | AE36: 歐陽子欣 | AF36: 29.5 | AG36: 20210264 | AH36: 33 | AI36: 蔡嘉傑 | AJ36: 49
Y37: 20180070 | Z37: 34 | AA37: 歐陽敏怡 | AB37: 56 | AG37: 20102052 | AH37: 34 | AI37: 鄺基業 | AJ37: 75.5
G43: 語文
G44: 數學
G45: 數選
G46: 英讀
G47: 歷史
G48: 地理
G49: 化學
G50: 物理
G51: 體育
G52: 電腦
G53: 公民

Sheet 工作表2
A1: 2024學年第一段 | D1: =摸底成績!G1 -> 英讀
A2: 本校 學籍號 | B2: 學號 | C2: 班級 | D2: 姓名 | E2: 摸底 | F2: 考分
A3: =摸底成績!A4 -> 20210198 | B3: =摸底成績!B4 -> 1 | C3: 高三1 | D3: =摸底成績!C4 -> 卜啟韜 | E3: =摸底成績!D4 -> 41.5
A4: =摸底成績!A5 -> 20230214 | B4: =摸底成績!B5 -> 2 | C4: 高三1 | D4: =摸底成績!C5 -> 尤鉑霖 | E4: =摸底成績!D5 -> 51
A5: =摸底成績!A6 -> 20190086 | B5: =摸底成績!B6 -> 3 | C5: 高三1 | D5: =摸底成績!C6 -> 尹智成 | E5: =摸底成績!D6 -> 63
A6: =摸底成績!A7 -> 20230295 | B6: =摸底成績!B7 -> 4 | C6: 高三1 | D6: =摸底成績!C7 -> 王清晨 | E6: =摸底成績!D7 -> 88.5
A7: =摸底成績!A8 -> 20220187 | B7: =摸底成績!B8 -> 5 | C7: 高三1 | D7: =摸底成績!C8 -> 何彥林 | E7: =摸底成績!D8 -> 72
A8: =摸底成績!A9 -> 20133010 | B8: =摸底成績!B9 -> 6 | C8: 高三1 | D8: =摸底成績!C9 -> 何詠宜 | E8: =摸底成績!D9 -> 56.5
A9: =摸底成績!A10 -> 20220081 | B9: =摸底成績!B10 -> 7 | C9: 高三1 | D9: =摸底成績!C10 -> 吳宇施 | E9: =摸底成績!D10 -> 72
A10: =摸底成績!A11 -> 20190179 | B10: =摸底成績!B11 -> 8 | C10: 高三1 | D10: =摸底成績!C11 -> 吳東濠 | E10: =摸底成績!D11 -> 81.5
A11: =摸底成績!A12 -> 20190009 | B11: =摸底成績!B12 -> 9 | C11: 高三1 | D11: =摸底成績!C12 -> 吳俊君 | E11: =摸底成績!D12 -> 63
A12: =摸底成績!A13 -> 20153119 | B12: =摸底成績!B13 -> 10 | C12: 高三1 | D12: =摸底成績!C13 -> 李杰成 | E12: =摸底成績!D13 -> 41
A13: =摸底成績!A14 -> 20220219 | B13: =摸底成績!B14 -> 11 | C13: 高三1 | D13: =摸底成績!C14 -> 李遠航 | E13: =摸底成績!D14 -> 74.5
A14: =摸底成績!A15 -> 20190044 | B14: =摸底成績!B15 -> 12 | C14: 高三1 | D14: =摸底成績!C15 -> 杜珮瑩 | E14: =摸底成績!D15 -> 38
... A30: =摸底成績!A31 -> 20220054 | B30: =摸底成績!B31 -> 28 | C30: 高三1 | D30: =摸底成績!C31 -> 龐宏俊 | E30: =摸底成績!D31 -> 80.5
A32: =摸底成績!E4 -> 20190194 | B32: =摸底成績!F4 -> 1 | C32: 高三2 | D32: =摸底成績!G4 -> 何亦琳 | E32: =摸底成績!H4 -> 91
A33: =摸底成績!E5 -> 20200072 | B33: =摸底成績!F5 -> 2 | C33: 高三2 | D33: =摸底成績!G5 -> 李鑫 | E33: =摸底成績!H5 -> 64
A34: =摸底成績!E6 -> 20102031 | B34: =摸底成績!F6 -> 3 | C34: 高三2 | D34: =摸底成績!G6 -> 杜家駿 | E34: =摸底成績!H6 -> 35
A35: =摸底成績!E7 -> 20180007 | B35: =摸底成績!F7 -> 4 | C35: 高三2 | D35: =摸底成績!G7 -> 林佩怡 | E35: =摸底成績!H7 -> 40
A36: =摸底成績!E8 -> 20102034 | B36: =摸底成績!F8 -> 5 | C36: 高三2 | D36: =摸底成績!G8 -> 林俊業 | E36: =摸底成績!H8 -> 64
A37: =摸底成績!E9 -> 20153065 | B37: =摸底成績!F9 -> 6 | C37: 高三2 | D37: =摸底成績!G9 -> 姚宏銘 | E37: =摸底成績!H9 -> 87.5
A38: =摸底成績!E10 -> 20220084 | B38: =摸底成績!F10 -> 7 | C38: 高三2 | D38: =摸底成績!G10 -> 唐詩堯 | E38: =摸底成績!H10 -> 65.5
A39: =摸底成績!E11 -> 20210163 | B39: =摸底成績!F11 -> 8 | C39: 高三2 | D39: =摸底成績!G11 -> 崔仕宇 | E39: =摸底成績!H11 -> 67.5
A40: =摸底成績!E12 -> 20190244 | B40: =摸底成績!F12 -> 9 | C40: 高三2 | D40: =摸底成績!G12 -> 梁嘉軒 | E40: =摸底成績!H12 -> 66
A41: =摸底成績!E13 -> 20220085 | B41: =摸底成績!F13 -> 10 | C41: 高三2 | D41: =摸底成績!G13 -> 梅俊銳 | E41: =摸底成績!H13 -> 60.5
A42: =摸底成績!E14 -> 20173030 | B42: =摸底成績!F14 -> 11 | C42: 高三2 | D42: =摸底成績!G14 -> 陳泓睿 | E42: =摸底成績!H14 -> 62.5
A43: =摸底成績!E15 -> 20220066 | B43: =摸底成績!F15 -> 12 | C43: 高三2 | D43: =摸底成績!G15 -> 陳智騫 | E43: =摸底成績!H15 -> 60
... A58: =摸底成績!E30 -> 20220120 | B58: =摸底成績!F30 -> 27 | C58: 高三2 | D58: =摸底成績!G30 -> 蘇聖鈞 | E58: =摸底成績!H30 -> 69
A60: =摸底成績!I4 -> 20230213 | B60: =摸底成績!J4 -> 1 | C60: 高三3 | D60: =摸底成績!K4 -> 尤嘉杰 | E60: =摸底成績!L4 -> 74.5
A61: =摸底成績!I5 -> 20190061 | B61: =摸底成績!J5 -> 2 | C61: 高三3 | D61: =摸底成績!K5 -> 尹霖 | E61: =摸底成績!L5 -> 74.5
A62: =摸底成績!I6 -> 20097078 | B62: =摸底成績!J6 -> 3 | C62: 高三3 | D62: =摸底成績!K6 -> 王子璇 | E62: =摸底成績!L6 -> 59
A63: =摸底成績!I7 -> 20200074 | B63: =摸底成績!J7 -> 4 | C63: 高三3 | D63: =摸底成績!K7 -> 古凌嫣 | E63: =摸底成績!L7 -> 88
A64: =摸底成績!I8 -> 20200175 | B64: =摸底成績!J8 -> 5 | C64: 高三3 | D64: =摸底成績!K8 -> 伍蕙君 | E64: =摸底成績!L8 -> 64
A65: =摸底成績!I9 -> 20220220 | B65: =摸底成績!J9 -> 6 | C65: 高三3 | D65: =摸底成績!K9 -> 何宇揚 | E65: =摸底成績!L9 -> 70
A66: =摸底成績!I10 -> 20210196 | B66: =摸底成績!J10 -> 7 | C66: 高三3 | D66: =摸底成績!K10 -> 李蓬承 | E66: =摸底成績!L10 -> 43.5
A67: =摸底成績!I11 -> 20102007 | B67: =摸底成績!J11 -> 8 | C67: 高三3 | D67: =摸底成績!K11 -> 林汶暉 | E67: =摸底成績!L11 -> 48
A68: =摸底成績!I12 -> 20220060 | B68: =摸底成績!J12 -> 9 | C68: 高三3 | D68: =摸底成績!K12 -> 林翰儒 | E68: =摸底成績!L12 -> 84.5
A69: =摸底成績!I13 -> 20163070 | B69: =摸底成績!J13 -> 10 | C69: 高三3 | D69: =摸底成績!K13 -> 胡善杰 | E69: =摸底成績!L13 -> 93
A70: =摸底成績!I14 -> 20153045 | B70: =摸底成績!J14 -> 11 | C70: 高三3 | D70: =摸底成績!K14 -> 梁家誠 | E70: =摸底成績!L14 -> 88.5
A71: =摸底成績!I15 -> 20190111 | B71: =摸底成績!J15 -> 12 | C71: 高三3 | D71: =摸底成績!K15 -> 許啓晟 | E71: =摸底成績!L15 -> 83.5
...
